Workbook

Sheet Tableau de bord
A1: AfricaVET — couverture éditoriale des 55 pays de l’Union africaine
A2: Inventaire exhaustif des articles au 25 août 2026 | Base vérifiable et priorités de rééquilibrage
A4: =COUNTA(Corpus!$A$2:$A$1045) -> 1044 | F4: =COUNTIF(Corpus!$I$2:$I$1045,"National") -> 551 | K4: =COUNTIF('Classement 55'!$D$5:$D$59,">0") -> 51 | P4: =COUNTIF('Classement 55'!$D$5:$D$59,0) -> 4
A8: Articles publiés | F8: Articles nationaux | K8: Pays couverts | P8: Pays sans article
A11: Pays | B11: Articles nationaux | N11: Région | O11: Articles
A12: ='Classement 55'!B5 -> Cameroun | B12: ='Classement 55'!D5 -> 112 | N12: ='Analyse régions'!A5 -> Afrique centrale | O12: ='Analyse régions'!C5 -> 163
A13: ='Classement 55'!B6 -> Sénégal | B13: ='Classement 55'!D6 -> 74 | N13: ='Analyse régions'!A6 -> Afrique de l'Ouest | O13: ='Analyse régions'!C6 -> 214
A14: ='Classement 55'!B7 -> Côte d’Ivoire | B14: ='Classement 55'!D7 -> 46 | N14: ='Analyse régions'!A7 -> Afrique de l'Est | O14: ='Analyse régions'!C7 -> 96
A15: ='Classement 55'!B8 -> Kenya | B15: ='Classement 55'!D8 -> 39 | N15: ='Analyse régions'!A8 -> Afrique australe | O15: ='Analyse régions'!C8 -> 41
A16: ='Classement 55'!B9 -> Burkina Faso | B16: ='Classement 55'!D9 -> 24 | N16: ='Analyse régions'!A9 -> Afrique du Nord | O16: ='Analyse régions'!C9 -> 37
A17: ='Classement 55'!B10 -> Afrique du Sud | B17: ='Classement 55'!D10 -> 23
A18: ='Classement 55'!B11 -> Nigeria | B18: ='Classement 55'!D11 -> 23
A19: ='Classement 55'!B12 -> Tchad | B19: ='Classement 55'!D12 -> 20
A20: ='Classement 55'!B13 -> RDC | B20: ='Classement 55'!D13 -> 16
A21: ='Classement 55'!B14 -> Maroc | B21: ='Classement 55'!D14 -> 15
A22: ='Classement 55'!B15 -> Togo | B22: ='Classement 55'!D15 -> 12
A23: ='Classement 55'!B16 -> Tanzanie | B23: ='Classement 55'!D16 -> 11
A24: ='Classement 55'!B17 -> Niger | B24: ='Classement 55'!D17 -> 10
A25: ='Classement 55'!B18 -> Ouganda | B25: ='Classement 55'!D18 -> 10
A26: ='Classement 55'!B19 -> Rwanda | B26: ='Classement 55'!D19 -> 10
A32: Constats clés et implications éditoriales | B32: Constats clés et implications éditoriales | C32: Constats clés et implications éditoriales | D32: Constats clés et implications éditoriales | E32: Constats clés et implications éditoriales | F32: Constats clés et implications éditoriales | G32: Constats clés et implications éditoriales | H32: Constats clés et implications éditoriales | I32: Constats clés et implications éditoriales | J32: Constats clés et implications éditoriales | K32: Constats clés et implications éditoriales | L32: Constats clés et implications éditoriales | M32: Constats clés et implications éditoriales | N32: Constats clés et implications éditoriales | O32: Constats clés et implications éditoriales | P32: Constats clés et implications éditoriales | Q32: Constats clés et implications éditoriales | R32: Constats clés et implications éditoriales | S32: Constats clés et implications éditoriales | T32: Constats clés et implications éditoriales
A34: • 53,5 % des articles nationaux sont concentrés sur cinq pays; les dix premiers représentent 71,1 %. • 4 États membres n’ont aucun article national identifié : Libye, RASD / Sahara occidental, Sao Tomé-et-Principe, Érythrée. • L’Afrique australe et l’Afrique du Nord affichent les plus faibles moyennes par pays. • Le champ pays du site n’est rempli que pour 61 articles sur 1 044 : la taxonomie géographique doit devenir obligatoire. • 202 attributions restent à vérifier, principalement des contenus génériques, mondiaux ou sans ancrage géographique explicite.
A42: Mesures de concentration | B42: Mesures de concentration | C42: Mesures de concentration | D42: Mesures de concentration | E42: Mesures de concentration | F42: Mesures de concentration | G42: Mesures de concentration | H42: Mesures de concentration | I42: Mesures de concentration | J42: Mesures de concentration | L42: Priorité d’action | M42: Priorité d’action | N42: Priorité d’action | O42: Priorité d’action | P42: Priorité d’action | Q42: Priorité d’action | R42: Priorité d’action | S42: Priorité d’action | T42: Priorité d’action
A43: Indicateur | B43: Valeur | L43: 1. Ouvrir une série “55 pays, 55 regards” en commençant par les 4 pays absents. 2. Fixer un plancher trimestriel pour les 35 pays à couverture nulle, très faible ou faible. 3. Rééquilibrer les sujets : faune/conservation ne représente que 15 articles, contre 224 pour One Health/zoonoses/santé publique. 4. Rendre obligatoires pays, région, langue d’origine et macrothème dans le CMS. 5. Réviser en priorité les 50 attributions nationales déduites uniquement du début du texte.
A44: Part des 2 premiers pays | B44: 0.33756806
A45: Part des 5 premiers pays | B45: 0.5353902
A46: Part des 10 premiers pays | B46: 0.71143376
A47: Indice de Gini (55 pays) | B47: 0.69341693

Sheet Vue journalistique
A1: AfricaVET — tableau de pilotage journalistique
A2: Auteurs, audience, impact, qualité éditoriale et priorités d’amélioration | Photographie au 25 août 2026
A4: 1044 | F4: 22786 | K4: 5 | P4: 21.829502
A8: Articles analysés | F8: Vues cumulées | K8: Auteurs normalisés | P8: Score moyen de complétude
A10: Auteurs — production et audience | B10: Auteurs — production et audience | C10: Auteurs — production et audience | D10: Auteurs — production et audience | E10: Auteurs — production et audience | F10: Auteurs — production et audience | G10: Auteurs — production et audience | H10: Auteurs — production et audience | N10: Articles au plus fort impact relatif | O10: Articles au plus fort impact relatif | P10: Articles au plus fort impact relatif | Q10: Articles au plus fort impact relatif | R10: Articles au plus fort impact relatif | S10: Articles au plus fort impact relatif | T10: Articles au plus fort impact relatif
A11: Auteur | B11: Articles | C11: Vues | D11: Vues/article | N11: Rang | O11: Article | P11: Auteur | Q11: Vues | R11: Vues/jour | S11: Score | T11: Niveau
A12: =Auteurs!A5 -> Malick Kane | B12: =Auteurs!B5 -> 798 | C12: =Auteurs!D5 -> 17485 | D12: =Auteurs!F5 -> 21.911028 | N12: 1 | O12: Coccidiose chez les poulets : ces signes discrets qui peu… | P12: Malick Kane | Q12: 181 | R12: 30.166667 | S12: 99.9 | T12: Très fort
A13: =Auteurs!A6 -> Flora J. Ingah | B13: =Auteurs!B6 -> 87 | C13: =Auteurs!D6 -> 1758 | D13: =Auteurs!F6 -> 20.206897 | N13: 2 | O13: Burkina Faso : l’opération « Zéro poulailler vide » veut … | P13: Malick Kane | Q13: 121 | R13: 24.2 | S13: 99.7 | T13: Très fort
A14: =Auteurs!A7 -> Mac Juliette Johngwe | B14: =Auteurs!B7 -> 85 | C14: =Auteurs!D7 -> 2074 | D14: =Auteurs!F7 -> 24.4 | N14: 3 | O14: PPR : les « épisystèmes », un levier stratégique pour le … | P14: Malick Kane | Q14: 91 | R14: 15.166667 | S14: 99.3 | T14: Très fort
A15: =Auteurs!A8 -> Simon Yaya | B15: =Auteurs!B8 -> 67 | C15: =Auteurs!D8 -> 1407 | D15: =Auteurs!F8 -> 21 | N15: 4 | O15: ZLECAf : les ministres africains veulent accélérer le com… | P15: Malick Kane | Q15: 226 | R15: 5.65 | S15: 99.2 | T15: Très fort
A16: =Auteurs!A9 -> Absan Bibou | B16: =Auteurs!B9 -> 7 | C16: =Auteurs!D9 -> 62 | D16: =Auteurs!F9 -> 8.8571429 | N16: 5 | O16: Cameroun : 93 stages ouverts dans des projets financés pa… | P16: Malick Kane | Q16: 75 | R16: 15 | S16: 99 | T16: Très fort
N17: 6 | O17: Pêche en Afrique : femmes et jeunes, piliers encore invis… | P17: Malick Kane | Q17: 111 | R17: 3.5806452 | S17: 98.3 | T17: Très fort
N18: 7 | O18: Peste des petits ruminants : symptômes, transmission, dia… | P18: Malick Kane | Q18: 145 | R18: 3.1521739 | S18: 98.2 | T18: Très fort
N19: 8 | O19: Sénégal : à Mbao, 1 000 ruches pour donner un nouvel élan… | P19: Malick Kane | Q19: 89 | R19: 3.56 | S19: 98 | T19: Très fort
N20: 9 | O20: Sudan: Vaccinating livestock amid conflict, a cross-borde… | P20: Malick Kane | Q20: 78 | R20: 3.25 | S20: 97.8 | T20: Très fort
N21: 10 | O21: Fientes anormales chez les poulets : ce que leur couleur … | P21: Malick Kane | Q21: 66 | R21: 5.5 | S21: 97.7 | T21: Très fort
A28: Constats spécialisés | B28: Constats spécialisés | C28: Constats spécialisés | D28: Constats spécialisés | E28: Constats spécialisés | F28: Constats spécialisés | G28: Constats spécialisés | H28: Constats spécialisés | I28: Constats spécialisés | J28: Constats spécialisés | K28: Constats spécialisés | L28: Constats spécialisés | M28: Constats spécialisés | N28: Constats spécialisés | O28: Constats spécialisés | P28: Constats spécialisés | Q28: Constats spécialisés | R28: Constats spécialisés | S28: Constats spécialisés | T28: Constats spécialisés
A29: • Malick Kane signe 76,4 % du corpus : la capacité de production est forte, mais la dépendance éditoriale est élevée. • Les 301 articles publiés en 2026 cumulent 11 003 vues, soit 48,3 % des vues du corpus. • L’article médian compte 16,5 vues; les dix articles les plus vus représentent 5,8 % des vues, ce qui indique une audience assez diffuse. • 385 articles sont détectés en anglais alors que la métadonnée de langue d’origine reste renseignée en français : le pilotage multilingue est faussé. • La complétude moyenne des éléments journalistiques et SEO n’est que de 21,8 / 100; ce score mesure les champs et la présentation, jamais la qualité du fond.
A38: Priorités de rédaction | B38: Priorités de rédaction | C38: Priorités de rédaction | D38: Priorités de rédaction | E38: Priorités de rédaction | F38: Priorités de rédaction | G38: Priorités de rédaction | H38: Priorités de rédaction | I38: Priorités de rédaction | J38: Priorités de rédaction | L38: Mesure d’audience à connecter | M38: Mesure d’audience à connecter | N38: Mesure d’audience à connecter | O38: Mesure d’audience à connecter | P38: Mesure d’audience à connecter | Q38: Mesure d’audience à connecter | R38: Mesure d’audience à connecter | S38: Mesure d’audience à connecter | T38: Mesure d’audience à connecter
A39: 1. Diversifier progressivement les signatures et formaliser les domaines de responsabilité de chaque auteur. 2. Fixer une check-list de publication : pays/région, langue, sources, crédit image, méta-titre, méta-description et validation. 3. Distinguer les formats : alerte, article d’actualité, analyse, guide pratique, entretien, reportage et dossier. 4. Suivre chaque mois le rendement par thème, pays, langue et auteur sans confondre volume et impact. 5. Conserver les titres complets dans le CMS, mais tester une longueur SEO plus resserrée pour l’affichage et le partage. | L39: Les vues de l’API sont cumulées par article. Elles ne remplacent pas les visiteurs uniques, les sessions, les sources de trafic, le temps d’engagement, la localisation de l’audience ou les conversions. Priorité : connecter GA4 ou Matomo, Search Console et des liens UTM cohérents pour Facebook, X, WhatsApp et la newsletter. Le tableau pourra alors mesurer la portée panafricaine, l’acquisition, la fidélisation et les conversions réelles.

Sheet Plan mise en œuvre
A1: AfricaVET — plan détaillé de mise en œuvre
A2: Feuille de route opérationnelle sur 12 mois | Responsables, échéances, livrables, KPI, dépendances et revues
A4: 24 | E4: 10 | I4: 12 | M4: 4
A8: Actions planifiées | E8: Actions des 30 premiers jours | I8: Horizon de transformation | M8: Revues stratégiques/an
A10: N° | B10: Phase | C10: Axe | D10: Action détaillée | E10: Priorité | F10: Responsable proposé | G10: Début | H10: Échéance | I10: Durée (j) | J10: Livrable attendu | K10: Indicateur de succès | L10: Cible | M10: Dépendances | N10: Revue / validation | O10: Statut
A11: 1 | B11: J0–J7 | C11: Gouvernance | D11: Mettre en place un comité éditorial restreint et valider les rôles décisionnels. | E11: P0 | F11: Direction / Rédaction en chef | G11: 46260 | H11: 46266 | I11: =H11-G11+1 -> 7 | J11: Note de gouvernance et calendrier des réunions | K11: Comité désigné et première réunion tenue | L11: 100 % | M11: Disponibilité des responsables | N11: Direction | O11: À lancer
A12: 2 | B12: J0–J7 | C12: Gouvernance | D12: Valider la matrice RACI pour commande, validation scientifique, publication, correction et retrait. | E12: P0 | F12: Rédaction en chef | G12: 46260 | H12: 46268 | I12: =H12-G12+1 -> 9 | J12: Matrice RACI approuvée | K12: Aucune étape critique sans responsable | L12: 100 % | M12: Action 1 | N12: Comité éditorial | O12: À lancer
A13: 3 | B13: J0–J30 | C13: CMS / métadonnées | D13: Rendre obligatoires pays ou région, langue réelle, auteur normalisé, catégorie, sources, crédit image, méta-titre et méta-description. | E13: P0 | F13: Webmaster / CMS | G13: 46261 | H13: 46280 | I13: =H13-G13+1 -> 20 | J13: Formulaire CMS révisé avec contrôles bloquants | K13: Nouveaux articles complets sur les champs obligatoires | L13: 100 % | M13: Accès technique au CMS | N13: Rédaction en chef | O13: À lancer
A14: 4 | B14: J0–J15 | C14: Auteurs | D14: Nettoyer les signatures, créer une fiche normalisée par auteur et éviter les doublons d’espacement ou d’orthographe. | E14: P0 | F14: Webmaster + Rédaction | G14: 46261 | H14: 46270 | I14: =H14-G14+1 -> 10 | J14: Référentiel unique des auteurs | K14: 5 auteurs actuels correctement normalisés | L14: 100 % | M14: Liste des comptes CMS | N14: Rédaction en chef | O14: À lancer
A15: 5 | B15: J0–J30 | C15: Audience | D15: Auditer puis installer ou fiabiliser GA4 ou Matomo, Search Console et les événements de conversion. | E15: P0 | F15: Responsable analytics / Webmaster | G15: 46261 | H15: 46280 | I15: =H15-G15+1 -> 20 | J15: Plan de marquage et tableau de contrôle | K15: Visiteurs, sessions, engagement et conversions mesurables | L15: Suivi actif | M15: Accès domaine et consentement cookies | N15: Direction | O15: À lancer
A16: 6 | B16: J0–J15 | C16: Distribution | D16: Adopter une convention UTM unique pour Facebook, X, WhatsApp, newsletter et partenaires. | E16: P0 | F16: Audience / Réseaux sociaux | G16: 46262 | H16: 46272 | I16: =H16-G16+1 -> 11 | J16: Guide UTM et générateur de liens | K16: Liens sociaux conformes | L16: ≥ 80 % | M16: Action 5 | N16: Rédaction en chef | O16: À lancer
A17: 7 | B17: J0–J15 | C17: Qualité | D17: Instaurer une check-list prépublication et une double validation pour les contenus sanitaires, scientifiques ou sensibles. | E17: P0 | F17: Rédaction en chef + Référent scientifique | G17: 46260 | H17: 46270 | I17: =H17-G17+1 -> 11 | J17: Check-list, journal de validation et règles d’escalade | K17: Contenus sensibles validés avant publication | L17: 100 % | M17: Disponibilité du référent | N17: Comité éditorial | O17: À lancer
A18: 8 | B18: J0–J30 | C18: Couverture UA | D18: Commander et publier un premier article pour la Libye, la RASD/Sahara occidental, Sao Tomé-et-Principe et l’Érythrée. | E18: P0 | F18: Coordination éditoriale | G18: 46261 | H18: 46295 | I18: =H18-G18+1 -> 35 | J18: Quatre articles nationaux vérifiés | K18: Pays UA couverts | L18: 55/55 | M18: Accès à des sources fiables | N18: Comité éditorial | O18: À lancer
A19: 9 | B19: J0–J30 | C19: Multilingue | D19: Corriger le paramétrage de langue d’origine et traiter les 385 incohérences FR/EN identifiées. | E19: P0 | F19: Webmaster + Édition linguistique | G19: 46262 | H19: 46295 | I19: =H19-G19+1 -> 34 | J19: Métadonnées linguistiques corrigées | K19: Incohérences restantes | L19: 0 | M19: Action 3 | N19: Rédaction en chef | O19: À lancer
A20: 10 | B20: J0–J30 | C20: Éthique / corrections | D20: Publier une politique de correction, mise à jour, droit de réponse, conflits d’intérêts et contenus sponsorisés. | E20: P0 | F20: Direction / Rédaction en chef | G20: 46262 | H20: 46285 | I20: =H20-G20+1 -> 24 | J20: Politique publique et procédure interne | K20: Corrections tracées avec date et motif | L20: 100 % | M20: Validation juridique si nécessaire | N20: Direction | O20: À lancer
A21: 11 | B21: J31–J90 | C21: Archives | D21: Corriger en priorité les métadonnées des 200 articles les plus vus et des contenus sanitaires à fort risque. | E21: P1 | F21: Équipe CMS / Éditeurs | G21: 46286 | H21: 46356 | I21: =H21-G21+1 -> 71 | J21: Lot de 200 articles remis à niveau | K21: Articles prioritaires complétés | L21: 200 | M21: Actions 3 et 7 | N21: Rédaction en chef | O21: À lancer
A22: 12 | B22: J31–J90 | C22: Réseau | D22: Recruter ou formaliser au moins cinq correspondants régionaux et clarifier rémunération, commande et validation. | E22: P1 | F22: Direction / Coordination Afrique | G22: 46266 | H22: 46326 | I22: =H22-G22+1 -> 61 | J22: Fiches de mission et vivier de correspondants | K22: Régions UA avec point focal actif | L22: 5/5 | M22: Budget et contrats | N22: Direction | O22: À lancer
... A34: 24 | B34: M7–M12 | C34: Impact / pérennité | D34: Publier un rapport annuel d’impact éditorial et arrêter le plan de ressources, partenariats et revenus de l’année suivante. | E34: P3 | F34: Direction + Rédaction | G34: 46569 | H34: 46624 | I34: =H34-G34+1 -> 56 | J34: Rapport annuel et plan 2027–2028 | K34: Décisions documentées et budget validé | L34: 1 rapport | M34: Données annuelles complètes | N34: Direction | O34: À lancer

Sheet Plan 90 jours
A1: AfricaVET — calendrier opérationnel des 90 premiers jours
A2: Séquençage hebdomadaire du 26 août au 30 novembre 2026 | Chaque semaine se termine par une preuve vérifiable
A4: Semaine | B4: Début | C4: Fin | D4: Objectif principal | E4: Actions essentielles | F4: Responsable proposé | G4: Livrable | H4: Preuve / KPI | I4: Point de revue | J4: Statut
A5: S0 | B5: 46260 | C5: 46264 | D5: Lancer la gouvernance | E5: Désigner le comité éditorial; valider le principe du RACI; geler les règles de nommage des auteurs. | F5: Direction / Rédaction en chef | G5: Note de lancement | H5: Comité nommé; réunion programmée | I5: 30 août | J5: À lancer
A6: S1 | B6: 46265 | C6: 46271 | D6: Sécuriser la publication | E6: Adopter check-list, double validation, politique de correction provisoire et référentiel auteurs. | F6: Rédaction en chef | G6: Pack qualité v1 | H6: 100 % des nouveaux contenus utilisent la check-list | I6: 6 septembre | J6: À lancer
A7: S2 | B7: 46272 | C7: 46278 | D7: Normaliser diffusion et analytics | E7: Finaliser UTM; auditer GA4/Matomo; définir conversions et tableau de bord minimum. | F7: Audience / Webmaster | G7: Plan de marquage | H7: UTM actifs; anomalies analytics documentées | I7: 13 septembre | J7: À lancer
A8: S3 | B8: 46279 | C8: 46285 | D8: Corriger le CMS | E8: Activer les champs obligatoires; tester langue, pays/région, sources, crédit image et SEO. | F8: Webmaster / CMS | G8: CMS v1 | H8: Publication bloquée si champ critique absent | I8: 20 septembre | J8: À lancer
A9: S4 | B9: 46286 | C9: 46292 | D9: Répartir les responsabilités | E9: Entretiens auteurs; validation des portefeuilles; confirmation des auteurs inactifs et besoins de recrutement. | F9: Rédaction en chef | G9: Plans individuels | H9: 5 décisions de positionnement documentées | I9: 27 septembre | J9: À lancer
A10: S5 | B10: 46293 | C10: 46299 | D10: Fermer les lacunes géographiques | E10: Publier ou sécuriser les quatre sujets des pays sans couverture; lancer “55 pays, 55 regards”. | F10: Coordination Afrique | G10: 4 articles / commandes | H10: 55 pays couverts ou commandes fermes | I10: 4 octobre | J10: À lancer
A11: S6 | B11: 46300 | C11: 46306 | D11: Installer la programmation | E11: Appliquer la grille de rubriques; lancer conférence hebdomadaire et calendrier à quatre semaines. | F11: Conférence de rédaction | G11: Calendrier octobre | H11: 100 % des commandes affectées à une rubrique | I11: 11 octobre | J11: À lancer
A12: S7 | B12: 46307 | C12: 46313 | D12: Améliorer la distribution | E12: Généraliser packs RS/SEO, CTA, UTM et calendrier Facebook/X/WhatsApp. | F12: Audience / Réseaux sociaux | G12: Pack distribution v1 | H12: ≥ 80 % des liens balisés | I12: 18 octobre | J12: À lancer
A13: S8 | B13: 46314 | C13: 46320 | D13: Commencer l’assainissement | E13: Traiter les 50 articles les plus vus : sources, SEO, image, pays, langue et mise à jour. | F13: Éditeurs / CMS | G13: Lot 1 corrigé | H13: 50 articles remis à niveau | I13: 25 octobre | J13: À lancer
A14: S9 | B14: 46321 | C14: 46327 | D14: Renforcer le réseau | E14: Sélectionner correspondants et relecteurs; valider conditions de collaboration et délais. | F14: Direction / Coordination Afrique | G14: Vivier validé | H14: 5 correspondants et 8 experts identifiés | I14: 1er novembre | J14: À lancer
A15: S10 | B15: 46328 | C15: 46334 | D15: Mesurer le premier cycle | E15: Produire le premier tableau mensuel : pays, thèmes, auteurs, qualité, audience et conversions. | F15: Analytics / Rédaction | G15: Dashboard octobre | H15: Revue tenue avant le 8 novembre | I15: 8 novembre | J15: À lancer
A16: S11 | B16: 46335 | C16: 46341 | D16: Optimiser les formats | E16: Comparer deux cohortes de titres, horaires et canaux; formaliser les premières décisions. | F16: Audience / Édition | G16: Note de test n°1 | H16: Résultats J+7 documentés | I16: 15 novembre | J16: À lancer
... A18: S13 | B18: 46349 | C18: 46356 | D18: Clore les 90 jours | E18: Atteindre 200 articles corrigés; réaliser la revue stratégique; approuver le plan des mois 4 à 6. | F18: Comité éditorial | G18: Rapport J+90 | H18: KPI, écarts, décisions et budget documentés | I18: 30 novembre | J18: À lancer
A21: Règle de pilotage | B21: Règle de pilotage | C21: Règle de pilotage | D21: Règle de pilotage | E21: Règle de pilotage | F21: Règle de pilotage | G21: Règle de pilotage | H21: Règle de pilotage | I21: Règle de pilotage | J21: Règle de pilotage
A22: Chaque fin de semaine, le responsable met à jour le statut, joint une preuve et indique tout blocage. Les sujets P0 non terminés à l’échéance sont automatiquement inscrits à l’ordre du jour du comité éditorial. La revue J+30 vérifie les fondations; la revue J+60 mesure l’adoption; la revue J+90 décide du passage à l’échelle.

Sheet Recommandations auteurs
A1: AfricaVET — recommandations détaillées par auteur
A2: Les objectifs individuels doivent être confirmés en entretien et contextualisés par disponibilité, commande, ancienneté et format
A4: Auteur | B4: Articles | C4: 90 derniers jours | D4: Vues/article | E4: Impact moyen | F4: Rôle éditorial proposé | G4: Forces observées | H4: Risques / écarts | I4: Rubriques prioritaires | J4: Actions J+30 | K4: Objectif J+90 | L4: Objectif à 6 mois | M4: Appui nécessaire | N4: KPI individuel | O4: Disponibilité
A5: Malick Kane | B5: 798 | C5: 147 | D5: 21.911028 | E5: 48.585965 | F5: Lead de production, mentor et garant de la continuité | G5: Volume exceptionnel; couverture de 49 pays; maîtrise de nombreux sujets; forte réactivité | H5: Dépendance de la rédaction; risque de surcharge; signatures trop concentrées; contrôle qualité difficile à ce volume | I5: Alertes majeures; analyses continentales; dossiers stratégiques; mentorat | J5: Réduire les tâches mécaniques; déléguer 20 % des brèves; valider deux modèles de dossier; documenter les méthodes | K5: Mentorer deux auteurs/correspondants; faire passer chaque article par la check-list; limiter les réécritures après publication | L5: Ramener sa part sous 68 % sans réduire la qualité; piloter un dossier majeur/mois; conduire la revue mensuelle | M5: Appui édition/SEO, desk de fact-checking et correspondants régionaux | N5: Complétude ≥ 70; corrections < 5 %; 2 auteurs mentorés; impact moyen maintenu | O5: Actif — à confirmer formellement
A6: Mac Juliette Johngwe | B6: 85 | C6: 29 | D6: 24.4 | E6: 63.330588 | F6: Référence proposée pour analyses et formats à fort impact | G6: Meilleure moyenne de vues et meilleur impact moyen; activité récente élevée; potentiel bilingue | H6: Portefeuille thématique à clarifier; besoin de consolider sources, SEO et traçabilité | I6: Analyses; innovations; élevage durable; data stories; entretiens experts | J6: Définir trois séries récurrentes; sécuriser un réseau de cinq experts; standardiser les sources et jeux de données | K6: Publier 8 à 12 contenus à forte valeur; au moins deux data stories ou analyses longues; former un pair | L6: Tenir un rendez-vous analytique bimensuel; impact moyen ≥ 65; complétude ≥ 75 | M6: Accès aux données, accompagnement visualisation et relecture scientifique | N6: Impact moyen ≥ 65; 30 % de formats longs; 100 % sources tracées | O6: Active — à confirmer formellement
A7: Flora J. Ingah | B7: 87 | C7: 0 | D7: 20.206897 | E7: 51.087356 | F7: Axe anglophone et suivi institutionnel, sous réserve de réactivation | G7: Corpus solide; part anglaise importante; bonne médiane de vues; expérience des sujets institutionnels | H7: Aucune publication récente sur 90 jours; rôle et disponibilité non confirmés | I7: Actualités anglophones; politiques sanitaires; institutions; entretiens | J7: Entretien de réactivation; choisir deux rubriques; actualiser la fiche auteur et les accès | K7: Si réactivée : 4 à 6 articles, dont deux interviews ou analyses anglophones; 100 % métadonnées | L7: Si active : 2 à 4 articles/mois; contribuer à la qualité linguistique EN | M7: Briefs réguliers, planning réaliste, soutien SEO et accès aux interlocuteurs | N7: Reprise effective; 100 % champs EN corrects; vues/article ≥ médiane | O7: À confirmer avant fixation des quotas
A8: Simon Yaya | B8: 67 | C8: 0 | D8: 21 | E8: 51.950746 | F8: Couverture pays et décryptages nationaux, sous réserve de réactivation | G8: Bonne médiane; capacité à traiter l’économie de l’élevage et les enjeux pays | H8: Aucune activité récente sur 90 jours; spécialisation et zone de couverture à préciser | I8: Dossiers pays; économie et marchés; élevage; voix des acteurs | J8: Entretien; confirmer pays/régions accessibles; proposer une série de trois sujets liés | K8: Si réactivé : 3 à 5 articles nationaux avec au moins trois voix locales par reportage | L8: Si actif : deux dossiers pays/mois; contribuer à “55 pays, 55 regards” | M8: Réseau de sources locales, budget reportage et accompagnement données | N8: Nombre de pays couverts; diversité des sources; impact moyen ≥ 55 | O8: À confirmer avant fixation des quotas
A9: Absan Bibou | B9: 7 | C9: 0 | D9: 8.8571429 | E9: 17.085714 | F9: Réactivation ciblée ou statut d’archive à décider | G9: Expérience historique sur One Health et santé publique | H9: Faible volume; aucune activité récente; données anciennes insuffisantes pour fixer une cible performante | I9: One Health; archives; mémoire institutionnelle; fact-check historique | J9: Vérifier disponibilité et intérêt; décider réactivation, contributeur ponctuel ou compte archivé | K9: Si réactivé : un article pilote accompagné et une évaluation éditoriale | L9: Si concluant : un contenu spécialisé/mois; sinon maintien comme archive sans quota | M9: Mentorat, brief très cadré et relecture rapprochée | N9: Décision de statut; qualité du pilote; respect de la check-list | O9: À décider dans les 30 jours
A12: Recommandations transversales pour l’équipe | B12: Recommandations transversales pour l’équipe | C12: Recommandations transversales pour l’équipe | D12: Recommandations transversales pour l’équipe | E12: Recommandations transversales pour l’équipe | F12: Recommandations transversales pour l’équipe | G12: Recommandations transversales pour l’équipe | H12: Recommandations transversales pour l’équipe | I12: Recommandations transversales pour l’équipe | J12: Recommandations transversales pour l’équipe | K12: Recommandations transversales pour l’équipe | L12: Recommandations transversales pour l’équipe | M12: Recommandations transversales pour l’équipe | N12: Recommandations transversales pour l’équipe | O12: Recommandations transversales pour l’équipe
A13: 1. Aucun quota individuel ne doit être confirmé sans entretien sur la disponibilité, le statut contractuel et les zones de compétence. 2. Séparer les objectifs de volume, qualité, impact, diversité des sources et couverture géographique. 3. Mettre en place un binôme auteur–éditeur pour chaque sujet complexe et un référent scientifique pour les contenus sanitaires sensibles. 4. Organiser une séance mensuelle de retour d’expérience à partir de deux articles réussis et de deux articles à améliorer. 5. Protéger le temps des auteurs à fort volume en confiant la mise en forme, le SEO, l’intégration CMS et la diffusion à des fonctions dédiées. 6. Recruter progressivement des correspondants afin de réduire la concentration sans fragiliser la cadence de publication.

Sheet Rubriques éditoriales
A1: AfricaVET — stratégie des rubriques et formats journalistiques
A2: Mix éditorial recommandé, exigences minimales, fréquence et indicateurs de succès
A4: 10 | E4: 1 | I4: 8 | M4: 55
A8: Formats structurés | E8: Mix éditorial total | I8: Piliers thématiques | M8: Série panafricaine
A10: Format / rubrique | B10: Objectif journalistique | C10: Part cible | D10: Fréquence indicative | E10: Longueur | F10: Sources minimales | G10: Éléments obligatoires | H10: Niveau de validation | I10: Canaux prioritaires | J10: KPI principal
A11: Alerte sanitaire / Breaking news | B11: Informer vite sans spéculation et préciser ce qui est confirmé, probable ou inconnu | C11: 0.12 | D11: Selon l’actualité | E11: 300–500 mots | F11: 2, dont 1 primaire | G11: Date/lieu; situation; source officielle; risques; prochaines étapes; mention de mise à jour | H11: Niveau 2 ou 3 | I11: Site; WhatsApp; X; Facebook | J11: Délai de publication; corrections; vues à J+1
A12: Actualité nationale | B12: Rendre compte d’une décision, campagne, événement ou évolution pays | C12: 0.23 | D12: Quotidienne | E12: 500–800 mots | F12: 2 indépendantes | G12: Angle pays; chiffres; citation; contexte; impact pour les acteurs; lien primaire | H12: Niveau 1 ou 2 | I12: Site; Facebook; WhatsApp | J12: Couverture pays; vues à J+7
A13: Analyse / décryptage | B13: Expliquer causes, conséquences, limites et options de politique publique | C13: 0.15 | D13: 2 à 3/semaine | E13: 900–1 500 mots | F13: 3 | G13: Problème; données; voix contradictoires; limites; scénarios; conclusion utile | H13: Niveau 2 | I13: Site; newsletter; LinkedIn | J13: Temps d’engagement; citations externes
A14: Reportage terrain | B14: Faire entendre les acteurs et documenter les réalités opérationnelles | C14: 0.1 | D14: 1 à 2/semaine | E14: 800–1 200 mots | F14: 3 voix locales | G14: Observation; contexte; citations; photos créditées; données locales; limites | H14: Niveau 2 | I14: Site; Facebook; WhatsApp; vidéo | J14: Diversité des voix; portée locale
A15: Entretien / Q&A | B15: Apporter expertise, responsabilité institutionnelle ou témoignage direct | C15: 0.08 | D15: 1 à 2/semaine | E15: 700–1 200 mots | F15: 1 invité + vérifications | G15: Présentation; questions structurées; citations validées; conflits d’intérêts; liens utiles | H15: Niveau 1 ou 2 | I15: Site; newsletter; réseaux | J15: Taux de lecture; reprises
A16: Guide pratique / fiche technique | B16: Répondre à un besoin concret des vétérinaires, éleveurs ou décideurs | C16: 0.1 | D16: 1 à 2/semaine | E16: 900–1 600 mots | F16: 3, dont normes | G16: Public cible; étapes; erreurs à éviter; quand consulter; sources; avertissement sanitaire | H16: Niveau 3 | I16: Site; WhatsApp; téléchargement | J16: Téléchargements; recherche organique
A17: Data story / cartographie | B17: Transformer données et cartes en information accessible et vérifiable | C17: 0.07 | D17: 2/mois | E17: 800–1 400 mots | F17: Jeu de données + méthode | G17: Source; période; définitions; méthode; graphique; limites; fichier téléchargeable | H17: Niveau 2 | I17: Site; newsletter; LinkedIn | J17: Backlinks; téléchargements; temps
A18: Dossier thématique | B18: Réunir plusieurs angles et formats sur une priorité panafricaine | C18: 0.05 | D18: 1/mois | E18: 1 500–2 500 mots | F18: 5 | G18: Chronologie; données; pays; experts; solutions; bibliographie; mises à jour | H18: Niveau 3 | I18: Site; newsletter; partenaires | J18: Durée de vie; abonnements; citations
A19: Opportunités / appels | B19: Diffuser rapidement une information vérifiée et directement exploitable | C19: 0.05 | D19: Selon disponibilité | E19: 300–600 mots | F19: 1 source primaire | G19: Éligibilité; montant; dates; procédure; contacts; lien officiel; alerte anti-fraude | H19: Niveau 1 | I19: Site; WhatsApp; Facebook | J19: Clics sortants; conversions
A20: Fact-check / correction | B20: Corriger une information virale ou documenter une erreur importante | C20: 0.05 | D20: Selon besoin | E20: 500–1 000 mots | F20: 3, priorité aux sources primaires | G20: Affirmation; verdict; preuves; méthode; correction; date; transparence | H20: Niveau 3 ou 4 | I20: Site; X; Facebook; WhatsApp | J20: Délai de correction; reprises fiables
A24: Rééquilibrage des piliers thématiques | B24: Rééquilibrage des piliers thématiques | C24: Rééquilibrage des piliers thématiques | D24: Rééquilibrage des piliers thématiques | E24: Rééquilibrage des piliers thématiques | F24: Rééquilibrage des piliers thématiques | G24: Rééquilibrage des piliers thématiques | H24: Rééquilibrage des piliers thématiques
A25: Pilier | B25: Articles actuels | C25: Part actuelle | D25: Cible 6 mois | E25: Cible 12 mois | F25: Rythme minimum | G25: Angle à renforcer | H25: Responsable proposé
A26: Actualités et analyses transversales | B26: 315 | C26: 0.30172414 | D26: 0.27 | E26: 0.25 | F26: À plafonner | G26: Reclasser les sujets trop génériques vers un pilier précis | H26: Rédaction en chef
A27: One Health, zoonoses et santé publique | B27: 224 | C27: 0.21455939 | D27: 0.18 | E27: 0.17 | F27: 3–4/mois | G27: Prévention, systèmes, communautés, économie de la santé | H27: Référent One Health
A28: Santé animale et maladies | B28: 139 | C28: 0.13314176 | D28: 0.17 | E28: 0.17 | F28: 3–4/mois | G28: Surveillance, diagnostic, vaccination, biosécurité | H28: Référent scientifique
A29: Élevage et productions animales | B29: 104 | C29: 0.099616858 | D29: 0.14 | E29: 0.14 | F29: 3/mois | G29: Productivité, bien-être, marchés, climat et pratiques | H29: Desk élevage
A30: Pêches et aquaculture | B30: 107 | C30: 0.10249042 | D30: 0.11 | E30: 0.11 | F30: 2–3/mois | G30: Santé aquatique, chaînes de valeur, pêche artisanale | H30: Desk aquatique
A31: Profession et services vétérinaires | B31: 73 | C31: 0.069923372 | D31: 0.09 | E31: 0.1 | F31: 2–3/mois | G31: Métiers, paraprofessionnels, réglementation, formation | H31: Desk profession
A32: Ressources, recherche et opportunités | B32: 67 | C32: 0.064176245 | D32: 0.07 | E32: 0.08 | F32: 2/mois | G32: Appels, outils, science africaine, transfert de connaissances | H32: Desk ressources
A33: Faune et conservation | B33: 15 | C33: 0.014367816 | D33: 0.07 | E33: 0.08 | F33: 2/mois | G33: Interfaces faune-bétail, coexistence, conservation et risques | H33: Correspondant faune
A36: Séries transversales recommandées | B36: Séries transversales recommandées | C36: Séries transversales recommandées | D36: Séries transversales recommandées | E36: Séries transversales recommandées | F36: Séries transversales recommandées | G36: Séries transversales recommandées | H36: Séries transversales recommandées | I36: Séries transversales recommandées | J36: Séries transversales recommandées | K36: Séries transversales recommandées | L36: Séries transversales recommandées | M36: Séries transversales recommandées | N36: Séries transversales recommandées | O36: Séries transversales recommandées | P36: Séries transversales recommandées | Q36: Séries transversales recommandées | R36: Séries transversales recommandées
A37: Série | B37: Promesse | C37: Fréquence | D37: Format dominant | E37: Objectif 6 mois | F37: KPI
A38: 55 pays, 55 regards | B38: Donner une place régulière à chaque État membre de l’UA | C38: 1/semaine | D38: Reportage ou dossier pays | E38: 18 pays publiés | F38: Pays couverts; sources locales
A39: Alerte santé animale | B39: Séparer faits confirmés, incertitudes et conseils opérationnels | C39: Selon besoin | D39: Alerte + mise à jour | E39: Protocole utilisé à 100 % | F39: Délai; corrections
A40: Métiers vétérinaires | B40: Valoriser vétérinaires, paraprofessionnels, laboratoires et services | C40: 1/semaine | D40: Portrait / entretien | E40: 24 professionnels | F40: Diversité pays et genre
A41: Data AfricaVET | B41: Expliquer une tendance par les données | C41: 2/mois | D41: Data story | E41: 12 analyses | F41: Backlinks; téléchargements
A42: Voix du terrain | B42: Faire entendre éleveurs, pêcheurs, communautés et agents locaux | C42: 1/semaine | D42: Reportage | E42: 24 sujets | F42: Nombre et diversité des voix
A43: Le point scientifique | B43: Traduire une publication ou norme en décision pratique | C43: 2/mois | D43: Analyse / guide | E43: 12 synthèses | F43: Temps de lecture; citations

Sheet Standards et workflow
A1: AfricaVET — standards journalistiques et workflow de publication
A2: Délais, responsabilités, preuves obligatoires, critères de blocage et protocole de correction
A4: Workflow éditorial standard | B4: Workflow éditorial standard | C4: Workflow éditorial standard | D4: Workflow éditorial standard | E4: Workflow éditorial standard | F4: Workflow éditorial standard | G4: Workflow éditorial standard | H4: Workflow éditorial standard | J4: Niveaux de validation | K4: Niveaux de validation | L4: Niveaux de validation | M4: Niveaux de validation | N4: Niveaux de validation
A5: Étape | B5: SLA indicatif | C5: Responsable (R) | D5: Approbateur (A) | E5: Consultés (C) | F5: Preuve obligatoire | G5: Critère Go / No-Go | H5: Action si échec | J5: Niveau | K5: Usage | L5: Validation minimale | M5: Délai cible | N5: Exemples
A6: 1. Proposition / commande | B6: ≤ 4 h actualité; 48 h dossier | C6: Auteur / Desk | D6: Rédaction en chef | E6: Coordination régionale | F6: Pitch avec angle, public, format et échéance | G6: Angle distinct et utile; absence de doublon | H6: Reformuler ou abandonner | J6: N1 — courant | K6: Information factuelle à faible risque | L6: Auteur + éditeur | M6: Même jour | N6: Opportunité; annonce; compte rendu
A7: 2. Pré-vérification | B7: Avant rédaction | C7: Auteur | D7: Éditeur | E7: Référent scientifique | F7: Liste initiale des sources et risques | G7: Au moins une source primaire accessible | H7: Suspendre et rechercher | J7: N2 — technique | K7: Sujet vétérinaire ou politique nécessitant contexte | L7: Auteur + éditeur + référent | M7: ≤ 24 h | N7: Campagne; réglementation; analyse
A8: 3. Collecte / entretiens | B8: Selon format | C8: Auteur | D8: Éditeur | E8: Experts / acteurs locaux | F8: Notes, enregistrements autorisés, documents et données | G8: Sources identifiées; citations vérifiables | H8: Compléter le reportage | J8: N3 — sensible | K8: Alerte maladie, santé publique, médicament ou conseil | L8: Double vérification + direction | M8: Avant diffusion | N8: Foyer; zoonose; diagnostic; guide
A9: 4. Rédaction | B9: 2 h à 7 jours | C9: Auteur | D9: Éditeur | E9: Référent thématique | F9: Version datée et liens sources | G9: Structure, angle, chiffres et contexte complets | H9: Retour auteur | J9: N4 — juridique / enquête | K9: Accusation, conflit, données personnelles ou investigation | L9: Direction + avis juridique | M9: Selon risque | N9: Fraude; responsabilité; droit de réponse
A10: 5. Relecture scientifique | B10: ≤ 4 h alerte; 24 h analyse | C10: Référent scientifique | D10: Rédaction en chef | E10: Laboratoire / institution | F10: Avis tracé dans le CMS | G10: Aucune erreur sanitaire majeure; incertitudes explicites | H10: Bloquer publication
A11: 6. Édition journalistique | B11: ≤ 4 h | C11: Éditeur | D11: Rédaction en chef | E11: Auteur | F11: Version révisée; titres et citations contrôlés | G11: Clarté, équilibre, attribution et conformité éthique | H11: Retour auteur / arbitrage
A12: 7. SEO et intégration CMS | B12: ≤ 1 h | C12: Webmaster / SEO | D12: Éditeur | E12: Auteur | F12: Tous champs obligatoires et aperçu social | G12: Score de complétude prépublication ≥ 80/100 | H12: Publication bloquée | J12: Protocole de correction | K12: Protocole de correction | L12: Protocole de correction | M12: Protocole de correction | N12: Protocole de correction
A13: 8. Validation finale | B13: ≤ 30 min | C13: Rédaction en chef | D13: Direction si sensible | E13: Juridique / partenaire | F13: Bon à publier horodaté | G13: Risque juridique et scientifique acceptable | H13: Escalade ou report | J13: 1. Corriger immédiatement l’erreur factuelle sans effacer l’historique. 2. Ajouter une note datée précisant ce qui a changé et pourquoi. 3. Informer les canaux sociaux si l’erreur a été diffusée largement. 4. Alerter les personnes ou institutions directement concernées. 5. En cas d’erreur majeure, revoir la cause, le workflow et la formation nécessaire.
A14: 9. Publication / diffusion | B14: Immédiat | C14: Webmaster + Réseaux sociaux | D14: Éditeur | E14: Auteur | F14: URL, UTM, pack Facebook/X/WhatsApp | G14: Liens, visuels et appels à l’action fonctionnels | H14: Corriger avant diffusion
A15: 10. Suivi / mise à jour | B15: J+1, J+7, J+30 | C15: Audience + Auteur | D15: Éditeur | E15: Référent scientifique | F15: Vues, engagement, corrections et mises à jour | G15: Évolution importante intégrée; erreurs corrigées | H15: Ajouter note de mise à jour
A18: Check-list obligatoire avant publication | B18: Check-list obligatoire avant publication | C18: Check-list obligatoire avant publication | D18: Check-list obligatoire avant publication | E18: Check-list obligatoire avant publication | F18: Check-list obligatoire avant publication | G18: Check-list obligatoire avant publication | H18: Check-list obligatoire avant publication
A19: N° | B19: Contrôle | C19: Pourquoi | D19: Preuve dans le CMS | E19: Bloquant | F19: Responsable | G19: Quand
A20: 1 | B20: Angle et public cible explicites | C20: Éviter les contenus génériques | D20: Champ angle / brief | E20: Oui | F20: Éditeur | G20: Commande
A21: 2 | B21: Au moins deux sources; une primaire | C21: Réduire erreur et dépendance | D21: Liens et noms des sources | E21: Oui | F21: Auteur | G21: Avant rédaction
A22: 3 | B22: Chiffres, dates et unités vérifiés | C22: Éviter erreurs factuelles | D22: Document ou jeu de données | E22: Oui | F22: Auteur / Éditeur | G22: Relecture
A23: 4 | B23: Citation attribuée et fidèle | C23: Protéger les personnes et la crédibilité | D23: Notes ou validation | E23: Oui | F23: Auteur | G23: Relecture
A24: 5 | B24: Pays, région et portée renseignés | C24: Permettre le pilotage des 55 pays | D24: Champs CMS | E24: Oui | F24: Webmaster | G24: Intégration
A25: 6 | B25: Langue d’origine réelle renseignée | C25: Fiabiliser la publication bilingue | D25: Champ langue | E25: Oui | F25: Webmaster | G25: Intégration
A26: 7 | B26: Catégorie, macrothème et format corrects | C26: Éviter la rubrique générique | D26: Taxonomie CMS | E26: Oui | F26: Éditeur | G26: Intégration
A27: 8 | B27: Image autorisée, créditée et légendée | C27: Respecter droits et traçabilité | D27: Crédit, source, légende | E27: Oui | F27: Webmaster | G27: Intégration
A28: 9 | B28: Conflits d’intérêts et partenariat déclarés | C28: Préserver l’indépendance | D28: Mention publique si applicable | E28: Oui si applicable | F28: Éditeur | G28: Validation
A29: 10 | B29: Avertissement sanitaire présent | C29: Limiter les conseils dangereux | D29: Bloc disclaimer | E29: Oui si applicable | F29: Référent scientifique | G29: Validation
A30: 11 | B30: Méta-titre 50–60 caractères | C30: Améliorer affichage et recherche | D30: Champ SEO | E30: Oui | F30: SEO | G30: Intégration
A31: 12 | B31: Méta-description 140–160 caractères | C31: Clarifier la promesse de lecture | D31: Champ SEO | E31: Oui | F31: SEO | G31: Intégration
... A35: 16 | B35: Heure, auteur et validation tracés | C35: Assurer responsabilité et audit | D35: Journal CMS | E35: Oui | F35: Rédaction en chef | G35: Publication

Sheet KPI et gouvernance
A1: AfricaVET — KPI, cibles et gouvernance éditoriale
A2: Valeurs de référence au 25 août 2026 | Les cellules jaunes “Réalisé actuel” sont à mettre à jour lors de chaque revue
A4: 51 | E4: 21.829502 | I4: 0.76436782 | M4: 2
A8: Pays couverts | E8: Complétude moyenne | I8: Part du premier auteur | M8: Auteurs actifs sur 90 jours
A10: ID | B10: KPI | C10: Sens | D10: Référence | E10: Unité | F10: Cible J+30 | G10: Cible J+90 | H10: Cible 6 mois | I10: Cible 12 mois | J10: Réalisé actuel | K10: Écart vs J+90 | L10: Responsable | M10: Source | N10: Fréquence
A11: 1 | B11: Pays UA couverts | C11: Hausse | D11: 51 | E11: pays | F11: 55 | G11: 55 | H11: 55 | I11: 55 | J11: 51 | K11: =IF(C11="Hausse",J11-G11,G11-J11) -> -4 | L11: Coordination Afrique | M11: Classement 55 | N11: Mensuelle
A12: 2 | B12: Pays UA sans article national | C12: Baisse | D12: 4 | E12: pays | F12: 0 | G12: 0 | H12: 0 | I12: 0 | J12: 4 | K12: =IF(C12="Hausse",J12-G12,G12-J12) -> -4 | L12: Coordination Afrique | M12: Classement 55 | N12: Mensuelle
A13: 3 | B13: Part du premier auteur | C13: Baisse | D13: 0.76436782 | E13: % | F13: 0.74 | G13: 0.72 | H13: 0.68 | I13: 0.6 | J13: 0.76436782 | K13: =IF(C13="Hausse",J13-G13,G13-J13) -> -0.044367816 | L13: Rédaction en chef | M13: Auteurs | N13: Mensuelle
A14: 4 | B14: Auteurs actifs sur 90 jours | C14: Hausse | D14: 2 | E14: auteurs | F14: 3 | G14: 4 | H14: 6 | I14: 8 | J14: 2 | K14: =IF(C14="Hausse",J14-G14,G14-J14) -> -2 | L14: Rédaction en chef | M14: Auteurs | N14: Mensuelle
A15: 5 | B15: Score moyen de complétude | C15: Hausse | D15: 21.829502 | E15: /100 | F15: 35 | G15: 50 | H15: 70 | I15: 85 | J15: 21.829502 | K15: =IF(C15="Hausse",J15-G15,G15-J15) -> -28.170498 | L15: Qualité / CMS | M15: Qualité éditoriale | N15: Mensuelle
A16: 6 | B16: Champ pays renseigné dans le corpus | C16: Hausse | D16: 0.058429119 | E16: % | F16: 0.15 | G16: 0.25 | H16: 0.6 | I16: 0.95 | J16: 0.058429119 | K16: =IF(C16="Hausse",J16-G16,G16-J16) -> -0.19157088 | L16: Webmaster | M16: Corpus / API | N16: Mensuelle
A17: 7 | B17: Méta-titre renseigné | C17: Hausse | D17: 0.08908046 | E17: % | F17: 0.2 | G17: 0.35 | H17: 0.65 | I17: 0.95 | J17: 0.08908046 | K17: =IF(C17="Hausse",J17-G17,G17-J17) -> -0.26091954 | L17: SEO / CMS | M17: Qualité éditoriale | N17: Mensuelle
A18: 8 | B18: Méta-description renseignée | C18: Hausse | D18: 0.099616858 | E18: % | F18: 0.2 | G18: 0.35 | H18: 0.65 | I18: 0.95 | J18: 0.099616858 | K18: =IF(C18="Hausse",J18-G18,G18-J18) -> -0.25038314 | L18: SEO / CMS | M18: Qualité éditoriale | N18: Mensuelle
A19: 9 | B19: Crédit ou source image renseigné | C19: Hausse | D19: 0.0019157088 | E19: % | F19: 0.1 | G19: 0.25 | H19: 0.6 | I19: 0.95 | J19: 0.0019157088 | K19: =IF(C19="Hausse",J19-G19,G19-J19) -> -0.24808429 | L19: Webmaster | M19: Qualité éditoriale | N19: Mensuelle
A20: 10 | B20: Sources structurées renseignées | C20: Hausse | D20: 0 | E20: % | F20: 0.1 | G20: 0.25 | H20: 0.6 | I20: 0.95 | J20: 0 | K20: =IF(C20="Hausse",J20-G20,G20-J20) -> -0.25 | L20: Auteurs / Éditeurs | M20: Qualité éditoriale | N20: Mensuelle
A21: 11 | B21: Relecture ou vérification tracée | C21: Hausse | D21: 0 | E21: % | F21: 0.1 | G21: 0.25 | H21: 0.6 | I21: 0.95 | J21: 0 | K21: =IF(C21="Hausse",J21-G21,G21-J21) -> -0.25 | L21: Rédaction en chef | M21: Qualité éditoriale | N21: Mensuelle
A22: 12 | B22: Incohérences de langue FR/EN | C22: Baisse | D22: 385 | E22: articles | F22: 200 | G22: 0 | H22: 0 | I22: 0 | J22: 385 | K22: =IF(C22="Hausse",J22-G22,G22-J22) -> -385 | L22: Webmaster / Langues | M22: API / Corpus | N22: Hebdomadaire jusqu’à zéro
... A30: 20 | B30: Articles de la série 55 pays, 55 regards | C30: Hausse | D30: 0 | E30: articles | F30: 4 | G30: 12 | H30: 30 | I30: 55 | J30: 0 | K30: =IF(C30="Hausse",J30-G30,G30-J30) -> -12 | L30: Coordination Afrique | M30: Calendrier éditorial | N30: Mensuelle
A33: Instances et cadence de gouvernance | B33: Instances et cadence de gouvernance | C33: Instances et cadence de gouvernance | D33: Instances et cadence de gouvernance | E33: Instances et cadence de gouvernance | F33: Instances et cadence de gouvernance | G33: Instances et cadence de gouvernance | H33: Instances et cadence de gouvernance | I33: Instances et cadence de gouvernance | J33: Instances et cadence de gouvernance | K33: Instances et cadence de gouvernance | L33: Instances et cadence de gouvernance | M33: Instances et cadence de gouvernance | N33: Instances et cadence de gouvernance
A34: Instance | C34: Composition minimale | F34: Cadence | H34: Décisions attendues | J34: Entrées | M34: Sorties
A35: Desk quotidien | C35: Éditeur de permanence; auteur; réseaux sociaux | F35: 15 min chaque matin | H35: Priorités du jour; alertes; mises à jour | J35: Agenda, veille, incidents | M35: Liste de commandes et responsables
A36: Conférence hebdomadaire | C36: Rédaction en chef; auteurs; audience; CMS | F36: 1 fois/semaine | H36: Calendrier à 4 semaines; formats; pays; sources | J36: Pitchs, KPI courts, calendrier | M36: Commandes et arbitrages
A37: Revue audience et qualité | C37: Audience; SEO; CMS; éditeur | F37: 1 fois/semaine | H37: Corrections rapides; distribution; tests | J37: Top/bottom articles; UTM; erreurs | M37: Actions correctives
A38: Comité éditorial mensuel | C38: Direction; rédaction; scientifique; audience | F38: Avant le 7 du mois | H38: Ressources; écarts KPI; risques; partenariats | J38: Dashboard complet; corrections; plaintes | M38: Compte rendu et plan du mois
A39: Revue stratégique trimestrielle | C39: Direction; comité; partenaires invités si utile | F39: Trimestrielle | H39: Rééquilibrage pays/thèmes; réseau; budget | J39: Tendances 3 mois; audit échantillon | M39: Décisions stratégiques
A40: Rapport annuel | C40: Direction et rédaction | F40: Annuelle | H40: Priorités, ressources, indépendance et impact | J40: Données annuelles consolidées | M40: Rapport public et plan annuel
A43: RACI simplifié | B43: RACI simplifié | C43: RACI simplifié | D43: RACI simplifié | E43: RACI simplifié | F43: RACI simplifié | G43: RACI simplifié | H43: RACI simplifié | I43: RACI simplifié | J43: RACI simplifié | K43: RACI simplifié | L43: RACI simplifié | M43: RACI simplifié | N43: RACI simplifié
A44: Activité | C44: Direction | E44: Rédaction en chef | G44: Auteur | I44: Référent scientifique | K44: CMS / SEO | M44: Audience
A45: Stratégie annuelle | C45: A | E45: R | G45: C | I45: C | K45: C | M45: C
A46: Commande éditoriale | C46: I | E46: A/R | G46: C | I46: C | K46: I | M46: I
A47: Collecte et rédaction | C47: I | E47: A | G47: R | I47: C | K47: I | M47: I
A48: Validation scientifique | C48: I | E48: A | G48: C | I48: R | K48: I | M48: I
A49: SEO et intégration | C49: I | E49: A | G49: C | I49: C | K49: R | M49: C
A50: Publication et correction | C50: I | E50: A/R | G50: C | I50: C | K50: R | M50: C
A51: Diffusion et conversion | C51: I | E51: A | G51: C | I51: I | K51: C | M51: R
A52: Revue des KPI | C52: A | E52: R | G52: C | I52: C | K52: C | M52: R
A55: Légende RACI et règle d’escalade | B55: Légende RACI et règle d’escalade | C55: Légende RACI et règle d’escalade | D55: Légende RACI et règle d’escalade | E55: Légende RACI et règle d’escalade | F55: Légende RACI et règle d’escalade | G55: Légende RACI et règle d’escalade | H55: Légende RACI et règle d’escalade | I55: Légende RACI et règle d’escalade | J55: Légende RACI et règle d’escalade | K55: Légende RACI et règle d’escalade | L55: Légende RACI et règle d’escalade | M55: Légende RACI et règle d’escalade | N55: Légende RACI et règle d’escalade
A56: R = réalise; A = approuve et répond du résultat; C = consulté; I = informé. Une activité critique ne doit avoir qu’un seul A. Tout contenu de niveau 3 ou 4 est automatiquement escaladé à la rédaction en chef; la direction intervient si le risque juridique, institutionnel ou réputationnel est significatif.

Sheet Classement 55
A1: AfricaVET — classement éditorial des 55 États membres de l’UA
A2: Corpus au 25 août 2026 | Les comptes nationaux sont distincts des articles régionaux, continentaux et multinationaux
A4: Rang | B4: Pays | C4: Région UA | D4: Articles nationaux | E4: Confirmés | F4: Contextuels | G4: Mentions totales | H4: Part nationale | I4: Articles 2026 | J4: 12 derniers mois | K4: Première publication | L4: Dernière publication | M4: Jours sans article | N4: Niveau de couverture | O4: Priorité éditoriale | P4: Thème dominant | Q4: Diversité thématique | R4: Vues cumulées | S4: Attr. élevée | T4: Attr. moyenne
A5: 1 | B5: Cameroun | C5: Afrique centrale | D5: =COUNTIFS(Corpus!$F$2:$F$1045,B5,Corpus!$I$2:$I$1045,"National") -> 112 | E5: =COUNTIFS(Corpus!$F$2:$F$1045,B5,Corpus!$I$2:$I$1045,"National",Corpus!$J$2:$J$1045,"<>Début du texte") -> 105 | F5: =COUNTIFS(Corpus!$F$2:$F$1045,B5,Corpus!$I$2:$I$1045,"National",Corpus!$J$2:$J$1045,"Début du texte") -> 7 | G5: 123 | H5: =IFERROR(D5/SUM($D$5:$D$59),0) -> 0.20326679 | I5: =COUNTIFS(Corpus!$F$2:$F$1045,B5,Corpus!$I$2:$I$1045,"National",Corpus!$C$2:$C$1045,2026) -> 19 | J5: =COUNTIFS(Corpus!$F$2:$F$1045,B5,Corpus!$I$2:$I$1045,"National",Corpus!$B$2:$B$1045,">="&DATE(2025,8,26)) -> 29 | K5: 43918 | L5: 46259 | M5: 0 | N5: Très élevée | O5: P4 - maintenir/diversifier | P5: One Health, zoonoses et santé publique | Q5: 8 | R5: =SUMIFS(Corpus!$O$2:$O$1045,Corpus!$F$2:$F$1045,B5,Corpus!$I$2:$I$1045,"National") -> 2309 | S5: 104 | T5: 8
A6: 2 | B6: Sénégal | C6: Afrique de l'Ouest | D6: =COUNTIFS(Corpus!$F$2:$F$1045,B6,Corpus!$I$2:$I$1045,"National") -> 74 | E6: =COUNTIFS(Corpus!$F$2:$F$1045,B6,Corpus!$I$2:$I$1045,"National",Corpus!$J$2:$J$1045,"<>Début du texte") -> 72 | F6: =COUNTIFS(Corpus!$F$2:$F$1045,B6,Corpus!$I$2:$I$1045,"National",Corpus!$J$2:$J$1045,"Début du texte") -> 2 | G6: 93 | H6: =IFERROR(D6/SUM($D$5:$D$59),0) -> 0.13430127 | I6: =COUNTIFS(Corpus!$F$2:$F$1045,B6,Corpus!$I$2:$I$1045,"National",Corpus!$C$2:$C$1045,2026) -> 17 | J6: =COUNTIFS(Corpus!$F$2:$F$1045,B6,Corpus!$I$2:$I$1045,"National",Corpus!$B$2:$B$1045,">="&DATE(2025,8,26)) -> 22 | K6: 44647 | L6: 46259 | M6: 0 | N6: Très élevée | O6: P4 - maintenir/diversifier | P6: Actualités et analyses transversales | Q6: 7 | R6: =SUMIFS(Corpus!$O$2:$O$1045,Corpus!$F$2:$F$1045,B6,Corpus!$I$2:$I$1045,"National") -> 1279 | S6: 72 | T6: 2
A7: 3 | B7: Côte d’Ivoire | C7: Afrique de l'Ouest | D7: =COUNTIFS(Corpus!$F$2:$F$1045,B7,Corpus!$I$2:$I$1045,"National") -> 46 | E7: =COUNTIFS(Corpus!$F$2:$F$1045,B7,Corpus!$I$2:$I$1045,"National",Corpus!$J$2:$J$1045,"<>Début du texte") -> 43 | F7: =COUNTIFS(Corpus!$F$2:$F$1045,B7,Corpus!$I$2:$I$1045,"National",Corpus!$J$2:$J$1045,"Début du texte") -> 3 | G7: 51 | H7: =IFERROR(D7/SUM($D$5:$D$59),0) -> 0.083484574 | I7: =COUNTIFS(Corpus!$F$2:$F$1045,B7,Corpus!$I$2:$I$1045,"National",Corpus!$C$2:$C$1045,2026) -> 5 | J7: =COUNTIFS(Corpus!$F$2:$F$1045,B7,Corpus!$I$2:$I$1045,"National",Corpus!$B$2:$B$1045,">="&DATE(2025,8,26)) -> 8 | K7: 44645 | L7: 46245 | M7: 14 | N7: Très élevée | O7: P4 - maintenir/diversifier | P7: Pêches et aquaculture | Q7: 7 | R7: =SUMIFS(Corpus!$O$2:$O$1045,Corpus!$F$2:$F$1045,B7,Corpus!$I$2:$I$1045,"National") -> 713 | S7: 43 | T7: 3
A8: 4 | B8: Kenya | C8: Afrique de l'Est | D8: =COUNTIFS(Corpus!$F$2:$F$1045,B8,Corpus!$I$2:$I$1045,"National") -> 39 | E8: =COUNTIFS(Corpus!$F$2:$F$1045,B8,Corpus!$I$2:$I$1045,"National",Corpus!$J$2:$J$1045,"<>Début du texte") -> 32 | F8: =COUNTIFS(Corpus!$F$2:$F$1045,B8,Corpus!$I$2:$I$1045,"National",Corpus!$J$2:$J$1045,"Début du texte") -> 7 | G8: 59 | H8: =IFERROR(D8/SUM($D$5:$D$59),0) -> 0.070780399 | I8: =COUNTIFS(Corpus!$F$2:$F$1045,B8,Corpus!$I$2:$I$1045,"National",Corpus!$C$2:$C$1045,2026) -> 15 | J8: =COUNTIFS(Corpus!$F$2:$F$1045,B8,Corpus!$I$2:$I$1045,"National",Corpus!$B$2:$B$1045,">="&DATE(2025,8,26)) -> 19 | K8: 44642 | L8: 46259 | M8: 0 | N8: Très élevée | O8: P4 - maintenir/diversifier | P8: Actualités et analyses transversales | Q8: 8 | R8: =SUMIFS(Corpus!$O$2:$O$1045,Corpus!$F$2:$F$1045,B8,Corpus!$I$2:$I$1045,"National") -> 913 | S8: 32 | T8: 7
A9: 5 | B9: Burkina Faso | C9: Afrique de l'Ouest | D9: =COUNTIFS(Corpus!$F$2:$F$1045,B9,Corpus!$I$2:$I$1045,"National") -> 24 | E9: =COUNTIFS(Corpus!$F$2:$F$1045,B9,Corpus!$I$2:$I$1045,"National",Corpus!$J$2:$J$1045,"<>Début du texte") -> 21 | F9: =COUNTIFS(Corpus!$F$2:$F$1045,B9,Corpus!$I$2:$I$1045,"National",Corpus!$J$2:$J$1045,"Début du texte") -> 3 | G9: 27 | H9: =IFERROR(D9/SUM($D$5:$D$59),0) -> 0.043557169 | I9: =COUNTIFS(Corpus!$F$2:$F$1045,B9,Corpus!$I$2:$I$1045,"National",Corpus!$C$2:$C$1045,2026) -> 11 | J9: =COUNTIFS(Corpus!$F$2:$F$1045,B9,Corpus!$I$2:$I$1045,"National",Corpus!$B$2:$B$1045,">="&DATE(2025,8,26)) -> 15 | K9: 43707 | L9: 46257 | M9: 2 | N9: Élevée | O9: P4 - maintenir/diversifier | P9: Santé animale et maladies | Q9: 5 | R9: =SUMIFS(Corpus!$O$2:$O$1045,Corpus!$F$2:$F$1045,B9,Corpus!$I$2:$I$1045,"National") -> 692 | S9: 21 | T9: 3
A10: 6 | B10: Afrique du Sud | C10: Afrique australe | D10: =COUNTIFS(Corpus!$F$2:$F$1045,B10,Corpus!$I$2:$I$1045,"National") -> 23 | E10: =COUNTIFS(Corpus!$F$2:$F$1045,B10,Corpus!$I$2:$I$1045,"National",Corpus!$J$2:$J$1045,"<>Début du texte") -> 21 | F10: =COUNTIFS(Corpus!$F$2:$F$1045,B10,Corpus!$I$2:$I$1045,"National",Corpus!$J$2:$J$1045,"Début du texte") -> 2 | G10: 35 | H10: =IFERROR(D10/SUM($D$5:$D$59),0) -> 0.041742287 | I10: =COUNTIFS(Corpus!$F$2:$F$1045,B10,Corpus!$I$2:$I$1045,"National",Corpus!$C$2:$C$1045,2026) -> 14 | J10: =COUNTIFS(Corpus!$F$2:$F$1045,B10,Corpus!$I$2:$I$1045,"National",Corpus!$B$2:$B$1045,">="&DATE(2025,8,26)) -> 16 | K10: 44515 | L10: 46255 | M10: 4 | N10: Élevée | O10: P4 - maintenir/diversifier | P10: Santé animale et maladies | Q10: 8 | R10: =SUMIFS(Corpus!$O$2:$O$1045,Corpus!$F$2:$F$1045,B10,Corpus!$I$2:$I$1045,"National") -> 596 | S10: 19 | T10: 4
A11: 7 | B11: Nigeria | C11: Afrique de l'Ouest | D11: =COUNTIFS(Corpus!$F$2:$F$1045,B11,Corpus!$I$2:$I$1045,"National") -> 23 | E11: =COUNTIFS(Corpus!$F$2:$F$1045,B11,Corpus!$I$2:$I$1045,"National",Corpus!$J$2:$J$1045,"<>Début du texte") -> 20 | F11: =COUNTIFS(Corpus!$F$2:$F$1045,B11,Corpus!$I$2:$I$1045,"National",Corpus!$J$2:$J$1045,"Début du texte") -> 3 | G11: 30 | H11: =IFERROR(D11/SUM($D$5:$D$59),0) -> 0.041742287 | I11: =COUNTIFS(Corpus!$F$2:$F$1045,B11,Corpus!$I$2:$I$1045,"National",Corpus!$C$2:$C$1045,2026) -> 6 | J11: =COUNTIFS(Corpus!$F$2:$F$1045,B11,Corpus!$I$2:$I$1045,"National",Corpus!$B$2:$B$1045,">="&DATE(2025,8,26)) -> 9 | K11: 44708 | L11: 46258 | M11: 1 | N11: Élevée | O11: P4 - maintenir/diversifier | P11: Actualités et analyses transversales | Q11: 7 | R11: =SUMIFS(Corpus!$O$2:$O$1045,Corpus!$F$2:$F$1045,B11,Corpus!$I$2:$I$1045,"National") -> 480 | S11: 20 | T11: 3
A12: 8 | B12: Tchad | C12: Afrique centrale | D12: =COUNTIFS(Corpus!$F$2:$F$1045,B12,Corpus!$I$2:$I$1045,"National") -> 20 | E12: =COUNTIFS(Corpus!$F$2:$F$1045,B12,Corpus!$I$2:$I$1045,"National",Corpus!$J$2:$J$1045,"<>Début du texte") -> 19 | F12: =COUNTIFS(Corpus!$F$2:$F$1045,B12,Corpus!$I$2:$I$1045,"National",Corpus!$J$2:$J$1045,"Début du texte") -> 1 | G12: 26 | H12: =IFERROR(D12/SUM($D$5:$D$59),0) -> 0.036297641 | I12: =COUNTIFS(Corpus!$F$2:$F$1045,B12,Corpus!$I$2:$I$1045,"National",Corpus!$C$2:$C$1045,2026) -> 7 | J12: =COUNTIFS(Corpus!$F$2:$F$1045,B12,Corpus!$I$2:$I$1045,"National",Corpus!$B$2:$B$1045,">="&DATE(2025,8,26)) -> 11 | K12: 44939 | L12: 46259 | M12: 0 | N12: Élevée | O12: P4 - maintenir/diversifier | P12: Actualités et analyses transversales | Q12: 4 | R12: =SUMIFS(Corpus!$O$2:$O$1045,Corpus!$F$2:$F$1045,B12,Corpus!$I$2:$I$1045,"National") -> 486 | S12: 19 | T12: 1
